Workbook

Sheet 発注書中身
B1: 宛名 | D1: No. | E1: 摘要 | F1: 数量 | G1: 単価 | H1: 金額 | J1: 備考
A2: 前 | D2: =IF(E2="","",1) | H2: =IF(AND(F2<>"",G2<>""),F2*G2,"")
A3: 会社名 | D3: =IF(E3="","",IF(MAX($D$2:D2)="","",MAX($D$2:D2)+1)) | H3: =IF(AND(F3<>"",G3<>""),F3*G3,"")
A4: 後 | B4: 御中 | D4: =IF(E4="","",IF(MAX($D$2:D3)="","",MAX($D$2:D3)+1)) | H4: =IF(AND(F4<>"",G4<>""),F4*G4,"")
D5: =IF(E5="","",IF(MAX($D$2:D4)="","",MAX($D$2:D4)+1)) | H5: =IF(AND(F5<>"",G5<>""),F5*G5,"")
B6: 年月日 | D6: =IF(E6="","",IF(MAX($D$2:D5)="","",MAX($D$2:D5)+1)) | H6: =IF(AND(F6<>"",G6<>""),F6*G6,"")
A7: 年 | B7: 2026 | D7: =IF(E7="","",IF(MAX($D$2:D6)="","",MAX($D$2:D6)+1)) | H7: =IF(AND(F7<>"",G7<>""),F7*G7,"")
A8: 月 | B8: 4 | D8: =IF(E8="","",IF(MAX($D$2:D7)="","",MAX($D$2:D7)+1)) | H8: =IF(AND(F8<>"",G8<>""),F8*G8,"")
A9: 日 | B9: 1 | D9: =IF(E9="","",IF(MAX($D$2:D8)="","",MAX($D$2:D8)+1)) | H9: =IF(AND(F9<>"",G9<>""),F9*G9,"")
A10: 通番号 | B10: 1 | D10: =IF(E10="","",IF(MAX($D$2:D9)="","",MAX($D$2:D9)+1)) | H10: =IF(AND(F10<>"",G10<>""),F10*G10,"")
D11: =IF(E11="","",IF(MAX($D$2:D10)="","",MAX($D$2:D10)+1)) | H11: =IF(AND(F11<>"",G11<>""),F11*G11,"")
B12: 条件 | D12: =IF(E12="","",IF(MAX($D$2:D11)="","",MAX($D$2:D11)+1)) | H12: =IF(AND(F12<>"",G12<>""),F12*G12,"")
A13: 件名 | D13: =IF(E13="","",IF(MAX($D$2:D12)="","",MAX($D$2:D12)+1)) | H13: =IF(AND(F13<>"",G13<>""),F13*G13,"")
A14: 納期 | D14: =IF(E14="","",IF(MAX($D$2:D13)="","",MAX($D$2:D13)+1)) | H14: =IF(AND(F14<>"",G14<>""),F14*G14,"")
A15: 納品場所 | B15: 〒802-0001 北九州市小倉北区浅野二丁目14番3号 あるあるcity2号館小倉B1F | D15: =IF(E15="","",IF(MAX($D$2:D14)="","",MAX($D$2:D14)+1)) | H15: =IF(AND(F15<>"",G15<>""),F15*G15,"")
A16: 支払条件 | B16: 月末締翌月末支払 | D16: =IF(E16="","",IF(MAX($D$2:D15)="","",MAX($D$2:D15)+1)) | H16: =IF(AND(F16<>"",G16<>""),F16*G16,"")
A17: 見積No. | D17: =IF(E17="","",IF(MAX($D$2:D16)="","",MAX($D$2:D16)+1)) | H17: =IF(AND(F17<>"",G17<>""),F17*G17,"")
D18: =IF(E18="","",IF(MAX($D$2:D17)="","",MAX($D$2:D17)+1)) | H18: =IF(AND(F18<>"",G18<>""),F18*G18,"")
D19: =IF(E19="","",IF(MAX($D$2:D18)="","",MAX($D$2:D18)+1)) | H19: =IF(AND(F19<>"",G19<>""),F19*G19,"")
D20: =IF(E20="","",IF(MAX($D$2:D19)="","",MAX($D$2:D19)+1)) | H20: =IF(AND(F20<>"",G20<>""),F20*G20,"")
D21: =IF(E21="","",IF(MAX($D$2:D20)="","",MAX($D$2:D20)+1)) | H21: =IF(AND(F21<>"",G21<>""),F21*G21,"")
D22: =IF(E22="","",IF(MAX($D$2:D21)="","",MAX($D$2:D21)+1)) | H22: =IF(AND(F22<>"",G22<>""),F22*G22,"")
D23: =IF(E23="","",IF(MAX($D$2:D22)="","",MAX($D$2:D22)+1)) | H23: =IF(AND(F23<>"",G23<>""),F23*G23,"")
D24: =IF(E24="","",IF(MAX($D$2:D23)="","",MAX($D$2:D23)+1)) | H24: =IF(AND(F24<>"",G24<>""),F24*G24,"")
D25: =IF(E25="","",IF(MAX($D$2:D24)="","",MAX($D$2:D24)+1)) | H25: =IF(AND(F25<>"",G25<>""),F25*G25,"")
D26: =IF(E26="","",IF(MAX($D$2:D25)="","",MAX($D$2:D25)+1)) | H26: =IF(AND(F26<>"",G26<>""),F26*G26,"")
H27: =IF(SUM(H2:H26)=0,"",SUM(H2:H26))
H28: =IFERROR(H29-H27,"")
H29: =IFERROR(ROUNDDOWN(H27*1.1,0),"")

Sheet 発注書
Z1: 発 注 書 | AM1: =CONCATENATE("発注No. ",TEXT(発注書中身!B7,"0000"),TEXT(発注書中身!B8,"00"),TEXT(発注書中身!B9,"00"),"-",TEXT(発注書中身!B10,"00"))
AM3: =CONCATENATE(TEXT(発注書中身!B7,"0000"),"年",TEXT(発注書中身!B8,"00"),"月",TEXT(発注書中身!B9,"00"),"日")
A5: =CONCATENATE(発注書中身!B2," ",発注書中身!B3," ",発注書中身!B4," 御中")
A8: =CONCATENATE("件名 : ",発注書中身!B13) | AN8: 請求先
A10: 下記の通り発注致します
A12: 納 期 | H12: =IF(発注書中身!B14="","",発注書中身!B14)
AN13: 〒802-0001
A14: 納 品 場 所 | H14: =IF(発注書中身!B15="","",発注書中身!B15)
AN15: 北九州市小倉北区浅野一丁目1番1号
AN17: ビエラ小倉1F DISCOVERYcoworking-103
A18: 支 払 条 件 | H18: =IF(発注書中身!B16="","",発注書中身!B16)
AN19: Tel : | AR19: 093-482-4622
A20: 見 積 No. | H20: =IF(発注書中身!B17="","",発注書中身!B17)
AN21: Fax : | AR21: 093-482-4623
A22: 合 計 金 額 | K22: =AZ80 | AD22: (税込)
AN23: Mail : | AR23: office@kiq-robotics.co.jp
A26: No. | D26: 摘要 | AH26: 数量 | AN26: 単価 | AZ26: 金額
A28: =IF(D28="","",1) | D28: =IF(発注書中身!E2="","",発注書中身!E2) | AH28: =IF(発注書中身!F2="","",発注書中身!F2) | AN28: =IF(発注書中身!G2="","",発注書中身!G2) | AZ28: =IF(AND(AH28<>"",AN28<>""),AH28*AN28,"")
A30: =IF(D30="","",IF(MAX($A$28:A28)="","",MAX($A$28:A28)+1)) | D30: =IF(発注書中身!E3="","",発注書中身!E3) | AH30: =IF(発注書中身!F3="","",発注書中身!F3) | AN30: =IF(発注書中身!G3="","",発注書中身!G3) | AZ30: =IF(AND(AH30<>"",AN30<>""),AH30*AN30,"")
A32: =IF(D32="","",IF(MAX($A$28:A30)="","",MAX($A$28:A30)+1)) | D32: =IF(発注書中身!E4="","",発注書中身!E4) | AH32: =IF(発注書中身!F4="","",発注書中身!F4) | AN32: =IF(発注書中身!G4="","",発注書中身!G4) | AZ32: =IF(AND(AH32<>"",AN32<>""),AH32*AN32,"")
A34: =IF(D34="","",IF(MAX($A$28:A32)="","",MAX($A$28:A32)+1)) | D34: =IF(発注書中身!E5="","",発注書中身!E5) | AH34: =IF(発注書中身!F5="","",発注書中身!F5) | AN34: =IF(発注書中身!G5="","",発注書中身!G5) | AZ34: =IF(AND(AH34<>"",AN34<>""),AH34*AN34,"")
A36: =IF(D36="","",IF(MAX($A$28:A34)="","",MAX($A$28:A34)+1)) | D36: =IF(発注書中身!E6="","",発注書中身!E6) | AH36: =IF(発注書中身!F6="","",発注書中身!F6) | AN36: =IF(発注書中身!G6="","",発注書中身!G6) | AZ36: =IF(AND(AH36<>"",AN36<>""),AH36*AN36,"")
A38: =IF(D38="","",IF(MAX($A$28:A36)="","",MAX($A$28:A36)+1)) | D38: =IF(発注書中身!E7="","",発注書中身!E7) | AH38: =IF(発注書中身!F7="","",発注書中身!F7) | AN38: =IF(発注書中身!G7="","",発注書中身!G7) | AZ38: =IF(AND(AH38<>"",AN38<>""),AH38*AN38,"")
A40: =IF(D40="","",IF(MAX($A$28:A38)="","",MAX($A$28:A38)+1)) | D40: =IF(発注書中身!E8="","",発注書中身!E8) | AH40: =IF(発注書中身!F8="","",発注書中身!F8) | AN40: =IF(発注書中身!G8="","",発注書中身!G8) | AZ40: =IF(AND(AH40<>"",AN40<>""),AH40*AN40,"")
A42: =IF(D42="","",IF(MAX($A$28:A40)="","",MAX($A$28:A40)+1)) | D42: =IF(発注書中身!E9="","",発注書中身!E9) | AH42: =IF(発注書中身!F9="","",発注書中身!F9) | AN42: =IF(発注書中身!G9="","",発注書中身!G9) | AZ42: =IF(AND(AH42<>"",AN42<>""),AH42*AN42,"")
A44: =IF(D44="","",IF(MAX($A$28:A42)="","",MAX($A$28:A42)+1)) | D44: =IF(発注書中身!E10="","",発注書中身!E10) | AH44: =IF(発注書中身!F10="","",発注書中身!F10) | AN44: =IF(発注書中身!G10="","",発注書中身!G10) | AZ44: =IF(AND(AH44<>"",AN44<>""),AH44*AN44,"")
A46: =IF(D46="","",IF(MAX($A$28:A44)="","",MAX($A$28:A44)+1)) | D46: =IF(発注書中身!E11="","",発注書中身!E11) | AH46: =IF(発注書中身!F11="","",発注書中身!F11) | AN46: =IF(発注書中身!G11="","",発注書中身!G11) | AZ46: =IF(AND(AH46<>"",AN46<>""),AH46*AN46,"")
A48: =IF(D48="","",IF(MAX($A$28:A46)="","",MAX($A$28:A46)+1)) | D48: =IF(発注書中身!E12="","",発注書中身!E12) | AH48: =IF(発注書中身!F12="","",発注書中身!F12) | AN48: =IF(発注書中身!G12="","",発注書中身!G12) | AZ48: =IF(AND(AH48<>"",AN48<>""),AH48*AN48,"")
A50: =IF(D50="","",IF(MAX($A$28:A48)="","",MAX($A$28:A48)+1)) | D50: =IF(発注書中身!E13="","",発注書中身!E13) | AH50: =IF(発注書中身!F13="","",発注書中身!F13) | AN50: =IF(発注書中身!G13="","",発注書中身!G13) | AZ50: =IF(AND(AH50<>"",AN50<>""),AH50*AN50,"")
A52: =IF(D52="","",IF(MAX($A$28:A50)="","",MAX($A$28:A50)+1)) | D52: =IF(発注書中身!E14="","",発注書中身!E14) | AH52: =IF(発注書中身!F14="","",発注書中身!F14) | AN52: =IF(発注書中身!G14="","",発注書中身!G14) | AZ52: =IF(AND(AH52<>"",AN52<>""),AH52*AN52,"")
A54: =IF(D54="","",IF(MAX($A$28:A52)="","",MAX($A$28:A52)+1)) | D54: =IF(発注書中身!E15="","",発注書中身!E15) | AH54: =IF(発注書中身!F15="","",発注書中身!F15) | AN54: =IF(発注書中身!G15="","",発注書中身!G15) | AZ54: =IF(AND(AH54<>"",AN54<>""),AH54*AN54,"")
A56: =IF(D56="","",IF(MAX($A$28:A54)="","",MAX($A$28:A54)+1)) | D56: =IF(発注書中身!E16="","",発注書中身!E16) | AH56: =IF(発注書中身!F16="","",発注書中身!F16) | AN56: =IF(発注書中身!G16="","",発注書中身!G16) | AZ56: =IF(AND(AH56<>"",AN56<>""),AH56*AN56,"")
A58: =IF(D58="","",IF(MAX($A$28:A56)="","",MAX($A$28:A56)+1)) | D58: =IF(発注書中身!E17="","",発注書中身!E17) | AH58: =IF(発注書中身!F17="","",発注書中身!F17) | AN58: =IF(発注書中身!G17="","",発注書中身!G17) | AZ58: =IF(AND(AH58<>"",AN58<>""),AH58*AN58,"")
A60: =IF(D60="","",IF(MAX($A$28:A58)="","",MAX($A$28:A58)+1)) | D60: =IF(発注書中身!E18="","",発注書中身!E18) | AH60: =IF(発注書中身!F18="","",発注書中身!F18) | AN60: =IF(発注書中身!G18="","",発注書中身!G18) | AZ60: =IF(AND(AH60<>"",AN60<>""),AH60*AN60,"")
A62: =IF(D62="","",IF(MAX($A$28:A60)="","",MAX($A$28:A60)+1)) | D62: =IF(発注書中身!E19="","",発注書中身!E19) | AH62: =IF(発注書中身!F19="","",発注書中身!F19) | AN62: =IF(発注書中身!G19="","",発注書中身!G19) | AZ62: =IF(AND(AH62<>"",AN62<>""),AH62*AN62,"")
A64: =IF(D64="","",IF(MAX($A$28:A62)="","",MAX($A$28:A62)+1)) | D64: =IF(発注書中身!E20="","",発注書中身!E20) | AH64: =IF(発注書中身!F20="","",発注書中身!F20) | AN64: =IF(発注書中身!G20="","",発注書中身!G20) | AZ64: =IF(AND(AH64<>"",AN64<>""),AH64*AN64,"")
A66: =IF(D66="","",IF(MAX($A$28:A64)="","",MAX($A$28:A64)+1)) | D66: =IF(発注書中身!E21="","",発注書中身!E21) | AH66: =IF(発注書中身!F21="","",発注書中身!F21) | AN66: =IF(発注書中身!G21="","",発注書中身!G21) | AZ66: =IF(AND(AH66<>"",AN66<>""),AH66*AN66,"")
A68: =IF(D68="","",IF(MAX($A$28:A66)="","",MAX($A$28:A66)+1)) | D68: =IF(発注書中身!E22="","",発注書中身!E22) | AH68: =IF(発注書中身!F22="","",発注書中身!F22) | AN68: =IF(発注書中身!G22="","",発注書中身!G22) | AZ68: =IF(AND(AH68<>"",AN68<>""),AH68*AN68,"")
A70: =IF(D70="","",IF(MAX($A$28:A68)="","",MAX($A$28:A68)+1)) | D70: =IF(発注書中身!E23="","",発注書中身!E23) | AH70: =IF(発注書中身!F23="","",発注書中身!F23) | AN70: =IF(発注書中身!G23="","",発注書中身!G23) | AZ70: =IF(AND(AH70<>"",AN70<>""),AH70*AN70,"")
A72: =IF(D72="","",IF(MAX($A$28:A70)="","",MAX($A$28:A70)+1)) | D72: =IF(発注書中身!E24="","",発注書中身!E24) | AH72: =IF(発注書中身!F24="","",発注書中身!F24) | AN72: =IF(発注書中身!G24="","",発注書中身!G24) | AZ72: =IF(AND(AH72<>"",AN72<>""),AH72*AN72,"")
...

Sheet リスト
A1: 宛名 | B1: 年 | C1: 月 | D1: 日 | E1: 通番号 | F1: 納品場所 | G1: 支払条件
B2: 2020 | C2: 1 | D2: 1 | E2: 1 | F2: 別途打合せ | G2: 別途打合せ
A3: 株式会社 | B3: 2021 | C3: 2 | D3: 2 | E3: 2 | F3: 〒802-0001 北九州市小倉北区浅野一丁目3番1号 | G3: 貴社指定方法
A4: (株) | B4: 2022 | C4: 3 | D4: 3 | E4: 3 | F4: 〒802-0001 北九州市小倉北区浅野一丁目1番1号 ビエラ小倉1F DISCOVERYcoworking-103 | G4: 月末締翌月末支払
A5: 有限会社 | B5: 2023 | C5: 4 | D5: 4 | E5: 4 | F5: 〒802-0001 北九州市小倉北区浅野3-8-1 AIMビル6F | G5: 前入金
A6: (有) | B6: 2024 | C6: 5 | D6: 5 | E6: 5 | F6: 〒804-0015 北九州市戸畑区仙水町1-1 4号棟255
A7: 合同会社 | B7: 2025 | C7: 6 | D7: 6 | E7: 6 | F7: 〒802-0001 北九州市小倉北区浅野二丁目14番3号 あるあるcity2号館小倉B1F
A8: (同) | B8: 2026 | C8: 7 | D8: 7 | E8: 7 | F8: 〒471-0834 愛知県豊田市寿町6-1 豊田油気株式会社 杉森裕貴 様
B9: 2027 | C9: 8 | D9: 8 | E9: 8
B10: 2028 | C10: 9 | D10: 9 | E10: 9
B11: 2029 | C11: 10 | D11: 10 | E11: 10
C12: 11 | D12: 11 | E12: 11
C13: 12 | D13: 12 | E13: 12
D14: 13 | E14: 13
D15: 14 | E15: 14
D16: 15 | E16: 15
D17: 16 | E17: 16
D18: 17 | E18: 17
D19: 18 | E19: 18
D20: 19 | E20: 19
D21: 20 | E21: 20
D22: 21 | E22: 21
D23: 22 | E23: 22
D24: 23 | E24: 23
D25: 24 | E25: 24
... D32: 31 | E32: 31
E33: 32
E34: 33
E35: 34
E36: 35
E37: 36
E38: 37
E39: 38
E40: 39
E41: 40
E42: 41
E43: 42
E44: 43
... E100: 99
